<?xml version="1.0" ?>
<robot name="converted_robot">
   <!--generated with mjcf_urdf_simple_converter (https://github.com/Yasu31/mjcf_urdf_simple_converter)-->
   <link name="world">
      <inertial>
         <origin xyz="0.0 0.0 0.0" rpy="0.0 0.0 0.0"/>
         <mass value="0.0"/>
         <inertia ixx="0.0" iyy="0.0" izz="0.0" ixy="0" ixz="0" iyz="0"/>
      </inertial>
   </link>
   <link name="pelvis">
      <inertial>
         <origin xyz="0.0 0.0 -0.07605" rpy="0.0 -0.0007982959576051663 0.0"/>
         <mass value="3.813"/>
         <inertia ixx="0.010549" iyy="0.0093089" izz="0.0079184" ixy="0" ixz="0" iyz="0"/>
      </inertial>
      <visual name="pelvis">
         <origin xyz="-1.9529809540945105e-07 -9.171826830955297e-07 -0.07637656182566167" rpy="0.00015990361525077814 -1.3952456967558646e-09 8.72554274986241e-06"/>
         <geometry>
            <mesh filename="package://bheema/unitree_g1/meshes/converted_pelvis_333333ff.obj"/>
         </geometry>
      </visual>
      <visual name="pelvis_contour_link">
         <origin xyz="0.0006870395627471365 2.401819341082137e-05 -0.07859361570716923" rpy="1.5471959140405038 0.0016128668451760308 1.5713580804039602"/>
         <geometry>
            <mesh filename="package://bheema/unitree_g1/meshes/converted_pelvis_contour_link_b2b2b2ff.obj"/>
         </geometry>
      </visual>
      <visual name="pelvis_contour_link">
         <origin xyz="0.0006870395627471365 2.401819341082137e-05 -0.07859361570716923" rpy="1.5471959140405038 0.0016128668451760308 1.5713580804039602"/>
         <geometry>
            <mesh filename="package://bheema/unitree_g1/meshes/converted_pelvis_contour_link_808080ff.obj"/>
         </geometry>
      </visual>
   </link>
   <link name="floating_base_joint_jointbody">
      <inertial>
         <origin xyz="0.0 0.0 0.0" rpy="0.0 0.0 0.0"/>
         <mass value="0.001"/>
         <inertia ixx="1e-09" iyy="1e-09" izz="1e-09" ixy="0" ixz="0" iyz="0"/>
      </inertial>
   </link>
   <joint type="fixed" name="floating_base_joint">
      <parent link="world"/>
      <child link="floating_base_joint_jointbody"/>
      <origin xyz="0.0 0.0 0.793" rpy="0.0 0.0 0.0"/>
   </joint>
   <joint type="fixed" name="floating_base_joint_offset">
      <parent link="floating_base_joint_jointbody"/>
      <child link="pelvis"/>
      <origin xyz="-0.0 -0.0 -0.0" rpy="0.0 0.0 0.0"/>
   </joint>
   <link name="left_hip_pitch_link">
      <inertial>
         <origin xyz="0.002741 0.047791 -0.02606" rpy="0.5988174572601404 0.040081048741047454 0.07544498172237224"/>
         <mass value="1.35"/>
         <inertia ixx="0.00181517" iyy="0.00153422" izz="0.00116212" ixy="0" ixz="0" iyz="0"/>
      </inertial>
      <visual name="left_hip_pitch_link">
         <origin xyz="-0.0008665585378783539 0.04711095469219488 -0.02629613521299048" rpy="0.6379983986511478 -0.1264411694845986 0.09532492244952906"/>
         <geometry>
            <mesh filename="package://bheema/unitree_g1/meshes/converted_left_hip_pitch_link_333333ff.obj"/>
         </geometry>
      </visual>
      <visual name="left_hip_pitch_link">
         <origin xyz="-0.0008665585378783539 0.04711095469219488 -0.02629613521299048" rpy="0.6379983986511478 -0.1264411694845986 0.09532492244952906"/>
         <geometry>
            <mesh filename="package://bheema/unitree_g1/meshes/converted_left_hip_pitch_link_808080ff.obj"/>
         </geometry>
      </visual>
   </link>
   <link name="left_hip_pitch_joint_jointbody">
      <inertial>
         <origin xyz="0.0 0.0 0.0" rpy="0.0 0.0 0.0"/>
         <mass value="0.001"/>
         <inertia ixx="1e-09" iyy="1e-09" izz="1e-09" ixy="0" ixz="0" iyz="0"/>
      </inertial>
   </link>
   <joint type="revolute" name="left_hip_pitch_joint">
      <parent link="pelvis"/>
      <child link="left_hip_pitch_joint_jointbody"/>
      <origin xyz="0.0 0.064452 -0.1027" rpy="0.0 0.0 0.0"/>
      <axis xyz="0.0 1.0 0.0"/>
      <limit lower="-2.5307" upper="2.8798" effort="100" velocity="100"/>
   </joint>
   <joint type="fixed" name="left_hip_pitch_joint_offset">
      <parent link="left_hip_pitch_joint_jointbody"/>
      <child link="left_hip_pitch_link"/>
      <origin xyz="-0.0 -0.0 -0.0" rpy="0.0 0.0 0.0"/>
   </joint>
   <link name="left_hip_roll_link">
      <inertial>
         <origin xyz="0.029812 -0.001045 -0.087934" rpy="-0.018174938093325495 0.413728392569112 -0.08635897759109293"/>
         <mass value="1.52"/>
         <inertia ixx="0.00254986" iyy="0.00241169" izz="0.00148755" ixy="0" ixz="0" iyz="0"/>
      </inertial>
      <visual name="left_hip_roll_link">
         <origin xyz="0.03567396132978256 -0.00036361950676388214 -0.06771372727135536" rpy="-0.010588636566934557 0.35304791455611695 -0.01581117623964661"/>
         <geometry>
            <mesh filename="package://bheema/unitree_g1/meshes/converted_left_hip_roll_link_b2b2b2ff.obj"/>
         </geometry>
      </visual>
      <visual name="left_hip_roll_link">
         <origin xyz="0.03567396132978256 -0.00036361950676388214 -0.06771372727135536" rpy="-0.010588636566934557 0.35304791455611695 -0.01581117623964661"/>
         <geometry>
            <mesh filename="package://bheema/unitree_g1/meshes/converted_left_hip_roll_link_808080ff.obj"/>
         </geometry>
      </visual>
   </link>
   <link name="left_hip_roll_joint_jointbody">
      <inertial>
         <origin xyz="0.0 0.0 0.0" rpy="0.0 0.0 0.0"/>
         <mass value="0.001"/>
         <inertia ixx="1e-09" iyy="1e-09" izz="1e-09" ixy="0" ixz="0" iyz="0"/>
      </inertial>
   </link>
   <joint type="revolute" name="left_hip_roll_joint">
      <parent link="left_hip_pitch_link"/>
      <child link="left_hip_roll_joint_jointbody"/>
      <origin xyz="0.0 0.052 -0.030465" rpy="0.0 -0.17489998429394227 0.0"/>
      <axis xyz="1.0 0.0 0.0"/>
      <limit lower="-0.5236" upper="2.9671" effort="100" velocity="100"/>
   </joint>
   <joint type="fixed" name="left_hip_roll_joint_offset">
      <parent link="left_hip_roll_joint_jointbody"/>
      <child link="left_hip_roll_link"/>
      <origin xyz="-0.0 -0.0 -0.0" rpy="0.0 0.0 0.0"/>
   </joint>
   <link name="left_hip_yaw_link">
      <inertial>
         <origin xyz="-0.057709 -0.010981 -0.15078" rpy="0.5540907790916816 0.0305964976672084 1.8013748980475472"/>
         <mass value="1.702"/>
         <inertia ixx="0.00776166" iyy="0.00717575" izz="0.00160139" ixy="0" ixz="0" iyz="0"/>
      </inertial>
      <visual name="left_hip_yaw_link">
         <origin xyz="-0.030698236099282915 -0.0031575123714920315 -0.09263915858615535" rpy="0.4652267475865616 0.01573260394194187 1.632172512777883"/>
         <geometry>
            <mesh filename="package://bheema/unitree_g1/meshes/converted_left_hip_yaw_link_b2b2b2ff.obj"/>
         </geometry>
      </visual>
      <visual name="left_hip_yaw_link">
         <origin xyz="-0.030698236099282915 -0.0031575123714920315 -0.09263915858615535" rpy="0.4652267475865616 0.01573260394194187 1.632172512777883"/>
         <geometry>
            <mesh filename="package://bheema/unitree_g1/meshes/converted_left_hip_yaw_link_808080ff.obj"/>
         </geometry>
      </visual>
   </link>
   <link name="left_hip_yaw_joint_jointbody">
      <inertial>
         <origin xyz="0.0 0.0 0.0" rpy="0.0 0.0 0.0"/>
         <mass value="0.001"/>
         <inertia ixx="1e-09" iyy="1e-09" izz="1e-09" ixy="0" ixz="0" iyz="0"/>
      </inertial>
   </link>
   <joint type="revolute" name="left_hip_yaw_joint">
      <parent link="left_hip_roll_link"/>
      <child link="left_hip_yaw_joint_jointbody"/>
      <origin xyz="0.025001 0.0 -0.12412" rpy="0.0 0.0 0.0"/>
      <axis xyz="0.0 0.0 1.0"/>
      <limit lower="-2.7576" upper="2.7576" effort="100" velocity="100"/>
   </joint>
   <joint type="fixed" name="left_hip_yaw_joint_offset">
      <parent link="left_hip_yaw_joint_jointbody"/>
      <child link="left_hip_yaw_link"/>
      <origin xyz="-0.0 -0.0 -0.0" rpy="0.0 0.0 0.0"/>
   </joint>
   <link name="left_knee_link">
      <inertial>
         <origin xyz="0.005457 0.003964 -0.12074" rpy="-0.048519000764823184 0.054292689691372686 0.7832941703975453"/>
         <mass value="1.932"/>
         <inertia ixx="0.0113804" iyy="0.0112778" izz="0.00146458" ixy="0" ixz="0" iyz="0"/>
      </inertial>
      <visual name="left_knee_link">
         <origin xyz="0.01229041176367447 0.0027294407845290226 -0.12275210014016037" rpy="0.017322281158521413 0.0626182591539548 1.4189256886202024"/>
         <geometry>
            <mesh filename="package://bheema/unitree_g1/meshes/converted_left_knee_link_b2b2b2ff.obj"/>
         </geometry>
      </visual>
      <visual name="left_knee_link">
         <origin xyz="0.01229041176367447 0.0027294407845290226 -0.12275210014016037" rpy="0.017322281158521413 0.0626182591539548 1.4189256886202024"/>
         <geometry>
            <mesh filename="package://bheema/unitree_g1/meshes/converted_left_knee_link_808080ff.obj"/>
         </geometry>
      </visual>
   </link>
   <link name="left_knee_joint_jointbody">
      <inertial>
         <origin xyz="0.0 0.0 0.0" rpy="0.0 0.0 0.0"/>
         <mass value="0.001"/>
         <inertia ixx="1e-09" iyy="1e-09" izz="1e-09" ixy="0" ixz="0" iyz="0"/>
      </inertial>
   </link>
   <joint type="revolute" name="left_knee_joint">
      <parent link="left_hip_yaw_link"/>
      <child link="left_knee_joint_jointbody"/>
      <origin xyz="-0.078273 0.0021489 -0.17734" rpy="0.0 0.1748999842939425 0.0"/>
      <axis xyz="0.0 1.0 0.0"/>
      <limit lower="-0.087267" upper="2.8798" effort="100" velocity="100"/>
   </joint>
   <joint type="fixed" name="left_knee_joint_offset">
      <parent link="left_knee_joint_jointbody"/>
      <child link="left_knee_link"/>
      <origin xyz="-0.0 -0.0 -0.0" rpy="0.0 0.0 0.0"/>
   </joint>
   <link name="left_ankle_pitch_link">
      <inertial>
         <origin xyz="-0.007269 0.0 0.011137" rpy="1.098770384217672 0.0 1.5707963267948966"/>
         <mass value="0.074"/>
         <inertia ixx="1.89e-05" iyy="1.40805e-05" izz="6.9195e-06" ixy="0" ixz="0" iyz="0"/>
      </inertial>
      <visual name="left_ankle_pitch_link">
         <origin xyz="-0.004106198395375143 5.887730678462465e-05 -0.008573513698468344" rpy="0.5889383541831732 0.0 1.5707963267948966"/>
         <geometry>
            <mesh filename="package://bheema/unitree_g1/meshes/converted_left_ankle_pitch_link_b2b2b2ff.obj"/>
         </geometry>
      </visual>
      <visual name="left_ankle_pitch_link">
         <origin xyz="-0.004106198395375143 5.887730678462465e-05 -0.008573513698468344" rpy="0.5889383541831732 0.0 1.5707963267948966"/>
         <geometry>
            <mesh filename="package://bheema/unitree_g1/meshes/converted_left_ankle_pitch_link_808080ff.obj"/>
         </geometry>
      </visual>
   </link>
   <link name="left_ankle_pitch_joint_jointbody">
      <inertial>
         <origin xyz="0.0 0.0 0.0" rpy="0.0 0.0 0.0"/>
         <mass value="0.001"/>
         <inertia ixx="1e-09" iyy="1e-09" izz="1e-09" ixy="0" ixz="0" iyz="0"/>
      </inertial>
   </link>
   <joint type="revolute" name="left_ankle_pitch_joint">
      <parent link="left_knee_link"/>
      <child link="left_ankle_pitch_joint_jointbody"/>
      <origin xyz="0.0 -9.4445e-05 -0.30001" rpy="0.0 0.0 0.0"/>
      <axis xyz="0.0 1.0 0.0"/>
      <limit lower="-0.87267" upper="0.5236" effort="100" velocity="100"/>
   </joint>
   <joint type="fixed" name="left_ankle_pitch_joint_offset">
      <parent link="left_ankle_pitch_joint_jointbody"/>
      <child link="left_ankle_pitch_link"/>
      <origin xyz="-0.0 -0.0 -0.0" rpy="0.0 0.0 0.0"/>
   </joint>
   <link name="left_ankle_roll_link">
      <inertial>
         <origin xyz="0.026505 0.0 -0.016425" rpy="-3.1163585547559842 -1.5093660737206502 -0.025429175473726362"/>
         <mass value="0.608"/>
         <inertia ixx="0.00167218" iyy="0.0016161" izz="0.000217621" ixy="0" ixz="0" iyz="0"/>
      </inertial>
      <visual name="left_ankle_roll_link">
         <origin xyz="0.02646435804254272 7.351326310042785e-05 -0.014106210048355583" rpy="-3.119116147437704 -1.489394629219258 -0.02269621966958635"/>
         <geometry>
            <mesh filename="package://bheema/unitree_g1/meshes/converted_left_ankle_roll_link_333333ff.obj"/>
         </geometry>
      </visual>
   </link>
   <link name="left_ankle_roll_joint_jointbody">
      <inertial>
         <origin xyz="0.0 0.0 0.0" rpy="0.0 0.0 0.0"/>
         <mass value="0.001"/>
         <inertia ixx="1e-09" iyy="1e-09" izz="1e-09" ixy="0" ixz="0" iyz="0"/>
      </inertial>
   </link>
   <joint type="revolute" name="left_ankle_roll_joint">
      <parent link="left_ankle_pitch_link"/>
      <child link="left_ankle_roll_joint_jointbody"/>
      <origin xyz="0.0 0.0 -0.017558" rpy="0.0 0.0 0.0"/>
      <axis xyz="1.0 0.0 0.0"/>
      <limit lower="-0.2618" upper="0.2618" effort="100" velocity="100"/>
   </joint>
   <joint type="fixed" name="left_ankle_roll_joint_offset">
      <parent link="left_ankle_roll_joint_jointbody"/>
      <child link="left_ankle_roll_link"/>
      <origin xyz="-0.0 -0.0 -0.0" rpy="0.0 0.0 0.0"/>
   </joint>
   <link name="right_hip_pitch_link">
      <inertial>
         <origin xyz="0.002741 -0.047791 -0.02606" rpy="-0.5988174572601404 0.040081048741047454 -0.07544498172237224"/>
         <mass value="1.35"/>
         <inertia ixx="0.00181517" iyy="0.00153422" izz="0.00116212" ixy="0" ixz="0" iyz="0"/>
      </inertial>
      <visual name="right_hip_pitch_link">
         <origin xyz="-0.0008664703489512744 -0.04711005033357466 -0.026296623163099924" rpy="-0.6380379461504948 -0.1264811670174979 -0.09536771795197246"/>
         <geometry>
            <mesh filename="package://bheema/unitree_g1/meshes/converted_right_hip_pitch_link_333333ff.obj"/>
         </geometry>
      </visual>
      <visual name="right_hip_pitch_link">
         <origin xyz="-0.0008664703489512744 -0.04711005033357466 -0.026296623163099924" rpy="-0.6380379461504948 -0.1264811670174979 -0.09536771795197246"/>
         <geometry>
            <mesh filename="package://bheema/unitree_g1/meshes/converted_right_hip_pitch_link_808080ff.obj"/>
         </geometry>
      </visual>
   </link>
   <link name="right_hip_pitch_joint_jointbody">
      <inertial>
         <origin xyz="0.0 0.0 0.0" rpy="0.0 0.0 0.0"/>
         <mass value="0.001"/>
         <inertia ixx="1e-09" iyy="1e-09" izz="1e-09" ixy="0" ixz="0" iyz="0"/>
      </inertial>
   </link>
   <joint type="revolute" name="right_hip_pitch_joint">
      <parent link="pelvis"/>
      <child link="right_hip_pitch_joint_jointbody"/>
      <origin xyz="0.0 -0.064452 -0.1027" rpy="0.0 0.0 0.0"/>
      <axis xyz="0.0 1.0 0.0"/>
      <limit lower="-2.5307" upper="2.8798" effort="100" velocity="100"/>
   </joint>
   <joint type="fixed" name="right_hip_pitch_joint_offset">
      <parent link="right_hip_pitch_joint_jointbody"/>
      <child link="right_hip_pitch_link"/>
      <origin xyz="-0.0 -0.0 -0.0" rpy="0.0 0.0 0.0"/>
   </joint>
   <link name="right_hip_roll_link">
      <inertial>
         <origin xyz="0.029812 0.001045 -0.087934" rpy="0.018174938093325495 0.413728392569112 0.08635897759109293"/>
         <mass value="1.52"/>
         <inertia ixx="0.00254986" iyy="0.00241169" izz="0.00148755" ixy="0" ixz="0" iyz="0"/>
      </inertial>
      <visual name="right_hip_roll_link">
         <origin xyz="0.03567378883256972 0.0003616971847909951 -0.06771295458931689" rpy="0.01044591660946419 0.35305430937046367 0.015384555950420497"/>
         <geometry>
            <mesh filename="package://bheema/unitree_g1/meshes/converted_right_hip_roll_link_b2b2b2ff.obj"/>
         </geometry>
      </visual>
      <visual name="right_hip_roll_link">
         <origin xyz="0.03567378883256972 0.0003616971847909951 -0.06771295458931689" rpy="0.01044591660946419 0.35305430937046367 0.015384555950420497"/>
         <geometry>
            <mesh filename="package://bheema/unitree_g1/meshes/converted_right_hip_roll_link_808080ff.obj"/>
         </geometry>
      </visual>
   </link>
   <link name="right_hip_roll_joint_jointbody">
      <inertial>
         <origin xyz="0.0 0.0 0.0" rpy="0.0 0.0 0.0"/>
         <mass value="0.001"/>
         <inertia ixx="1e-09" iyy="1e-09" izz="1e-09" ixy="0" ixz="0" iyz="0"/>
      </inertial>
   </link>
   <joint type="revolute" name="right_hip_roll_joint">
      <parent link="right_hip_pitch_link"/>
      <child link="right_hip_roll_joint_jointbody"/>
      <origin xyz="0.0 -0.052 -0.030465" rpy="0.0 -0.17489998429394227 0.0"/>
      <axis xyz="1.0 0.0 0.0"/>
      <limit lower="-2.9671" upper="0.5236" effort="100" velocity="100"/>
   </joint>
   <joint type="fixed" name="right_hip_roll_joint_offset">
      <parent link="right_hip_roll_joint_jointbody"/>
      <child link="right_hip_roll_link"/>
      <origin xyz="-0.0 -0.0 -0.0" rpy="0.0 0.0 0.0"/>
   </joint>
   <link name="right_hip_yaw_link">
      <inertial>
         <origin xyz="-0.057709 0.010981 -0.15078" rpy="0.5540907790916816 -0.0305964976672084 1.3402177555422459"/>
         <mass value="1.702"/>
         <inertia ixx="0.00776166" iyy="0.00717575" izz="0.00160139" ixy="0" ixz="0" iyz="0"/>
      </inertial>
      <visual name="right_hip_yaw_link">
         <origin xyz="-0.030699656369028997 0.003158722541324976 -0.09263954567921404" rpy="0.465224825435285 -0.01567645225665637 1.5093289342853118"/>
         <geometry>
            <mesh filename="package://bheema/unitree_g1/meshes/converted_right_hip_yaw_link_b2b2b2ff.obj"/>
         </geometry>
      </visual>
      <visual name="right_hip_yaw_link">
         <origin xyz="-0.030699656369028997 0.003158722541324976 -0.09263954567921404" rpy="0.465224825435285 -0.01567645225665637 1.5093289342853118"/>
         <geometry>
            <mesh filename="package://bheema/unitree_g1/meshes/converted_right_hip_yaw_link_808080ff.obj"/>
         </geometry>
      </visual>
   </link>
   <link name="right_hip_yaw_joint_jointbody">
      <inertial>
         <origin xyz="0.0 0.0 0.0" rpy="0.0 0.0 0.0"/>
         <mass value="0.001"/>
         <inertia ixx="1e-09" iyy="1e-09" izz="1e-09" ixy="0" ixz="0" iyz="0"/>
      </inertial>
   </link>
   <joint type="revolute" name="right_hip_yaw_joint">
      <parent link="right_hip_roll_link"/>
      <child link="right_hip_yaw_joint_jointbody"/>
      <origin xyz="0.025001 0.0 -0.12412" rpy="0.0 0.0 0.0"/>
      <axis xyz="0.0 0.0 1.0"/>
      <limit lower="-2.7576" upper="2.7576" effort="100" velocity="100"/>
   </joint>
   <joint type="fixed" name="right_hip_yaw_joint_offset">
      <parent link="right_hip_yaw_joint_jointbody"/>
      <child link="right_hip_yaw_link"/>
      <origin xyz="-0.0 -0.0 -0.0" rpy="0.0 0.0 0.0"/>
   </joint>
   <link name="right_knee_link">
      <inertial>
         <origin xyz="0.005457 -0.003964 -0.12074" rpy="0.05497078739990324 0.047883485238203294 -0.7831774075963955"/>
         <mass value="1.932"/>
         <inertia ixx="0.011374" iyy="0.0112843" izz="0.00146452" ixy="0" ixz="0" iyz="0"/>
      </inertial>
      <visual name="right_knee_link">
         <origin xyz="0.012290840839311904 -0.0027284185571872224 -0.12275462830238623" rpy="0.01731356693980557 -0.06260061038118958 1.722781525449863"/>
         <geometry>
            <mesh filename="package://bheema/unitree_g1/meshes/converted_right_knee_link_b2b2b2ff.obj"/>
         </geometry>
      </visual>
      <visual name="right_knee_link">
         <origin xyz="0.012290840839311904 -0.0027284185571872224 -0.12275462830238623" rpy="0.01731356693980557 -0.06260061038118958 1.722781525449863"/>
         <geometry>
            <mesh filename="package://bheema/unitree_g1/meshes/converted_right_knee_link_808080ff.obj"/>
         </geometry>
      </visual>
   </link>
   <link name="right_knee_joint_jointbody">
      <inertial>
         <origin xyz="0.0 0.0 0.0" rpy="0.0 0.0 0.0"/>
         <mass value="0.001"/>
         <inertia ixx="1e-09" iyy="1e-09" izz="1e-09" ixy="0" ixz="0" iyz="0"/>
      </inertial>
   </link>
   <joint type="revolute" name="right_knee_joint">
      <parent link="right_hip_yaw_link"/>
      <child link="right_knee_joint_jointbody"/>
      <origin xyz="-0.078273 -0.0021489 -0.17734" rpy="0.0 0.1748999842939425 0.0"/>
      <axis xyz="0.0 1.0 0.0"/>
      <limit lower="-0.087267" upper="2.8798" effort="100" velocity="100"/>
   </joint>
   <joint type="fixed" name="right_knee_joint_offset">
      <parent link="right_knee_joint_jointbody"/>
      <child link="right_knee_link"/>
      <origin xyz="-0.0 -0.0 -0.0" rpy="0.0 0.0 0.0"/>
   </joint>
   <link name="right_ankle_pitch_link">
      <inertial>
         <origin xyz="-0.007269 0.0 0.011137" rpy="1.098770384217672 0.0 1.5707963267948966"/>
         <mass value="0.074"/>
         <inertia ixx="1.89e-05" iyy="1.40805e-05" izz="6.9195e-06" ixy="0" ixz="0" iyz="0"/>
      </inertial>
      <visual name="right_ankle_pitch_link">
         <origin xyz="-0.0041065949955294695 -5.9077733540970835e-05 -0.00857303102905033" rpy="0.5888330459747148 0.0 1.5707963267948966"/>
         <geometry>
            <mesh filename="package://bheema/unitree_g1/meshes/converted_right_ankle_pitch_link_b2b2b2ff.obj"/>
         </geometry>
      </visual>
      <visual name="right_ankle_pitch_link">
         <origin xyz="-0.0041065949955294695 -5.9077733540970835e-05 -0.00857303102905033" rpy="0.5888330459747148 0.0 1.5707963267948966"/>
         <geometry>
            <mesh filename="package://bheema/unitree_g1/meshes/converted_right_ankle_pitch_link_808080ff.obj"/>
         </geometry>
      </visual>
   </link>
   <link name="right_ankle_pitch_joint_jointbody">
      <inertial>
         <origin xyz="0.0 0.0 0.0" rpy="0.0 0.0 0.0"/>
         <mass value="0.001"/>
         <inertia ixx="1e-09" iyy="1e-09" izz="1e-09" ixy="0" ixz="0" iyz="0"/>
      </inertial>
   </link>
   <joint type="revolute" name="right_ankle_pitch_joint">
      <parent link="right_knee_link"/>
      <child link="right_ankle_pitch_joint_jointbody"/>
      <origin xyz="0.0 9.4445e-05 -0.30001" rpy="0.0 0.0 0.0"/>
      <axis xyz="0.0 1.0 0.0"/>
      <limit lower="-0.87267" upper="0.5236" effort="100" velocity="100"/>
   </joint>
   <joint type="fixed" name="right_ankle_pitch_joint_offset">
      <parent link="right_ankle_pitch_joint_jointbody"/>
      <child link="right_ankle_pitch_link"/>
      <origin xyz="-0.0 -0.0 -0.0" rpy="0.0 0.0 0.0"/>
   </joint>
   <link name="right_ankle_roll_link">
      <inertial>
         <origin xyz="0.026505 0.0 -0.016425" rpy="3.1163585547559842 -1.5093660737206502 0.025429175473726362"/>
         <mass value="0.608"/>
         <inertia ixx="0.00167218" iyy="0.0016161" izz="0.000217621" ixy="0" ixz="0" iyz="0"/>
      </inertial>
      <visual name="right_ankle_roll_link">
         <origin xyz="0.026469481697172777 -7.266444317600382e-05 -0.014106435744604889" rpy="3.1197956347207203 -1.4893919119936694 0.02204653443684479"/>
         <geometry>
            <mesh filename="package://bheema/unitree_g1/meshes/converted_right_ankle_roll_link_333333ff.obj"/>
         </geometry>
      </visual>
   </link>
   <link name="right_ankle_roll_joint_jointbody">
      <inertial>
         <origin xyz="0.0 0.0 0.0" rpy="0.0 0.0 0.0"/>
         <mass value="0.001"/>
         <inertia ixx="1e-09" iyy="1e-09" izz="1e-09" ixy="0" ixz="0" iyz="0"/>
      </inertial>
   </link>
   <joint type="revolute" name="right_ankle_roll_joint">
      <parent link="right_ankle_pitch_link"/>
      <child link="right_ankle_roll_joint_jointbody"/>
      <origin xyz="0.0 0.0 -0.017558" rpy="0.0 0.0 0.0"/>
      <axis xyz="1.0 0.0 0.0"/>
      <limit lower="-0.2618" upper="0.2618" effort="100" velocity="100"/>
   </joint>
   <joint type="fixed" name="right_ankle_roll_joint_offset">
      <parent link="right_ankle_roll_joint_jointbody"/>
      <child link="right_ankle_roll_link"/>
      <origin xyz="-0.0 -0.0 -0.0" rpy="0.0 0.0 0.0"/>
   </joint>
   <link name="waist_yaw_link">
      <inertial>
         <origin xyz="0.003494 0.000233 0.018034" rpy="-0.9922852679103331 -1.4364721998749919 -3.071000324169481"/>
         <mass value="0.214"/>
         <inertia ixx="0.000163531" iyy="0.000107714" izz="0.000102205" ixy="0" ixz="0" iyz="0"/>
      </inertial>
      <visual name="waist_yaw_link">
         <origin xyz="0.0038216219768146043 -3.0689794448813196e-05 0.015615160711480435" rpy="0.0023342417300675766 -1.4509452558075062 3.1381172725874373"/>
         <geometry>
            <mesh filename="package://bheema/unitree_g1/meshes/converted_waist_yaw_link_b2b2b2ff.obj"/>
         </geometry>
      </visual>
   </link>
   <link name="waist_yaw_joint_jointbody">
      <inertial>
         <origin xyz="0.0 0.0 0.0" rpy="0.0 0.0 0.0"/>
         <mass value="0.001"/>
         <inertia ixx="1e-09" iyy="1e-09" izz="1e-09" ixy="0" ixz="0" iyz="0"/>
      </inertial>
   </link>
   <joint type="revolute" name="waist_yaw_joint">
      <parent link="pelvis"/>
      <child link="waist_yaw_joint_jointbody"/>
      <origin xyz="0.0 0.0 0.0" rpy="0.0 0.0 0.0"/>
      <axis xyz="0.0 0.0 1.0"/>
      <limit lower="-2.618" upper="2.618" effort="100" velocity="100"/>
   </joint>
   <joint type="fixed" name="waist_yaw_joint_offset">
      <parent link="waist_yaw_joint_jointbody"/>
      <child link="waist_yaw_link"/>
      <origin xyz="-0.0 -0.0 -0.0" rpy="0.0 0.0 0.0"/>
   </joint>
   <link name="waist_roll_link">
      <inertial>
         <origin xyz="0.0 2.3e-05 0.0" rpy="1.5707963267948966 -1.5707963267948966 0.0"/>
         <mass value="0.086"/>
         <inertia ixx="8.245e-06" iyy="7.079e-06" izz="6.339e-06" ixy="0" ixz="0" iyz="0"/>
      </inertial>
      <visual name="waist_roll_link">
         <origin xyz="1.872641278022571e-10 1.310712222928039e-07 -2.381154591196088e-10" rpy="1.5707963267948966 0.0 1.5707963267948966"/>
         <geometry>
            <mesh filename="package://bheema/unitree_g1/meshes/converted_waist_roll_link_b2b2b2ff.obj"/>
         </geometry>
      </visual>
   </link>
   <link name="waist_roll_joint_jointbody">
      <inertial>
         <origin xyz="0.0 0.0 0.0" rpy="0.0 0.0 0.0"/>
         <mass value="0.001"/>
         <inertia ixx="1e-09" iyy="1e-09" izz="1e-09" ixy="0" ixz="0" iyz="0"/>
      </inertial>
   </link>
   <joint type="revolute" name="waist_roll_joint">
      <parent link="waist_yaw_link"/>
      <child link="waist_roll_joint_jointbody"/>
      <origin xyz="-0.0039635 0.0 0.044" rpy="0.0 0.0 0.0"/>
      <axis xyz="1.0 0.0 0.0"/>
      <limit lower="-0.52" upper="0.52" effort="100" velocity="100"/>
   </joint>
   <joint type="fixed" name="waist_roll_joint_offset">
      <parent link="waist_roll_joint_jointbody"/>
      <child link="waist_roll_link"/>
      <origin xyz="-0.0 -0.0 -0.0" rpy="0.0 0.0 0.0"/>
   </joint>
   <link name="torso_link">
      <inertial>
         <origin xyz="0.00203158 0.000339683 0.184568" rpy="-6.83596775902975e-05 0.039653906079409884 0.0026388830518288735"/>
         <mass value="7.818"/>
         <inertia ixx="0.121847" iyy="0.109825" izz="0.0273735" ixy="0" ixz="0" iyz="0"/>
      </inertial>
      <visual name="torso_link">
         <origin xyz="0.004859769271982111 0.002109824788911099 0.14751263696604375" rpy="0.003795258809795504 0.009096559313252373 0.004210900072470644"/>
         <geometry>
            <mesh filename="package://bheema/unitree_g1/meshes/converted_torso_link_b2b2b2ff.obj"/>
         </geometry>
      </visual>
      <visual name="torso_link">
         <origin xyz="0.004859769271982111 0.002109824788911099 0.14751263696604375" rpy="0.003795258809795504 0.009096559313252373 0.004210900072470644"/>
         <geometry>
            <mesh filename="package://bheema/unitree_g1/meshes/converted_torso_link_808080ff.obj"/>
         </geometry>
      </visual>
      <visual name="logo_link">
         <origin xyz="0.0030190916936811904 0.0011127782956188072 0.22746039917874727" rpy="3.030856524612828 -1.566921699321284 0.041169313305835065"/>
         <geometry>
            <mesh filename="package://bheema/unitree_g1/meshes/converted_logo_link_333333ff.obj"/>
         </geometry>
      </visual>
      <visual name="head_link">
         <origin xyz="0.007650942311808313 2.4814250502793286e-05 0.3851317963124549" rpy="2.916442025267819e-05 0.04559163418327694 0.00010977219856073105"/>
         <geometry>
            <mesh filename="package://bheema/unitree_g1/meshes/converted_head_link_333333ff.obj"/>
         </geometry>
      </visual>
      <visual name="head_link">
         <origin xyz="0.007650942311808313 2.4814250502793286e-05 0.3851317963124549" rpy="2.916442025267819e-05 0.04559163418327694 0.00010977219856073105"/>
         <geometry>
            <mesh filename="package://bheema/unitree_g1/meshes/converted_head_link_808080ff.obj"/>
         </geometry>
      </visual>
   </link>
   <link name="waist_pitch_joint_jointbody">
      <inertial>
         <origin xyz="0.0 0.0 0.0" rpy="0.0 0.0 0.0"/>
         <mass value="0.001"/>
         <inertia ixx="1e-09" iyy="1e-09" izz="1e-09" ixy="0" ixz="0" iyz="0"/>
      </inertial>
   </link>
   <joint type="revolute" name="waist_pitch_joint">
      <parent link="waist_roll_link"/>
      <child link="waist_pitch_joint_jointbody"/>
      <origin xyz="0.0 0.0 0.0" rpy="0.0 0.0 0.0"/>
      <axis xyz="0.0 1.0 0.0"/>
      <limit lower="-0.52" upper="0.52" effort="100" velocity="100"/>
   </joint>
   <joint type="fixed" name="waist_pitch_joint_offset">
      <parent link="waist_pitch_joint_jointbody"/>
      <child link="torso_link"/>
      <origin xyz="-0.0 -0.0 -0.0" rpy="0.0 0.0 0.0"/>
   </joint>
   <link name="left_shoulder_pitch_link">
      <inertial>
         <origin xyz="0.0 0.035892 -0.011628" rpy="-0.49834883517368966 -0.46079162371774673 1.732072902331688"/>
         <mass value="0.718"/>
         <inertia ixx="0.000465864" iyy="0.000432842" izz="0.000406394" ixy="0" ixz="0" iyz="0"/>
      </inertial>
      <visual name="left_shoulder_pitch_link">
         <origin xyz="-2.524160950152245e-05 0.03454218177570185 -0.008909194000553549" rpy="0.02893606614591482 -0.5899336882005926 1.504020067492158"/>
         <geometry>
            <mesh filename="package://bheema/unitree_g1/meshes/converted_left_shoulder_pitch_link_b2b2b2ff.obj"/>
         </geometry>
      </visual>
   </link>
   <link name="left_shoulder_pitch_joint_jointbody">
      <inertial>
         <origin xyz="0.0 0.0 0.0" rpy="0.0 0.0 0.0"/>
         <mass value="0.001"/>
         <inertia ixx="1e-09" iyy="1e-09" izz="1e-09" ixy="0" ixz="0" iyz="0"/>
      </inertial>
   </link>
   <joint type="revolute" name="left_shoulder_pitch_joint">
      <parent link="torso_link"/>
      <child link="left_shoulder_pitch_joint_jointbody"/>
      <origin xyz="0.0039563 0.10022 0.24778" rpy="0.2793090626390551 5.4948898537077184e-05 -0.00019158997789023302"/>
      <axis xyz="0.0 1.0 0.0"/>
      <limit lower="-3.0892" upper="2.6704" effort="100" velocity="100"/>
   </joint>
   <joint type="fixed" name="left_shoulder_pitch_joint_offset">
      <parent link="left_shoulder_pitch_joint_jointbody"/>
      <child link="left_shoulder_pitch_link"/>
      <origin xyz="-0.0 -0.0 -0.0" rpy="0.0 0.0 0.0"/>
   </joint>
   <link name="left_shoulder_roll_link">
      <inertial>
         <origin xyz="-0.000227 0.00727 -0.063243" rpy="-0.03765901158544349 0.018004551792828227 1.5865094247978933"/>
         <mass value="0.643"/>
         <inertia ixx="0.000691311" iyy="0.000618011" izz="0.000388977" ixy="0" ixz="0" iyz="0"/>
      </inertial>
      <visual name="left_shoulder_roll_link">
         <origin xyz="3.078866230346007e-05 0.007747256915819465 -0.03750622953852636" rpy="0.0034739091753315243 -0.0794133828154262 1.5701498870966804"/>
         <geometry>
            <mesh filename="package://bheema/unitree_g1/meshes/converted_left_shoulder_roll_link_b2b2b2ff.obj"/>
         </geometry>
      </visual>
   </link>
   <link name="left_shoulder_roll_joint_jointbody">
      <inertial>
         <origin xyz="0.0 0.0 0.0" rpy="0.0 0.0 0.0"/>
         <mass value="0.001"/>
         <inertia ixx="1e-09" iyy="1e-09" izz="1e-09" ixy="0" ixz="0" iyz="0"/>
      </inertial>
   </link>
   <joint type="revolute" name="left_shoulder_roll_joint">
      <parent link="left_shoulder_pitch_link"/>
      <child link="left_shoulder_roll_joint_jointbody"/>
      <origin xyz="0.0 0.038 -0.013831" rpy="-0.2792505189613739 0.0 0.0"/>
      <axis xyz="1.0 0.0 0.0"/>
      <limit lower="-1.5882" upper="2.2515" effort="100" velocity="100"/>
   </joint>
   <joint type="fixed" name="left_shoulder_roll_joint_offset">
      <parent link="left_shoulder_roll_joint_jointbody"/>
      <child link="left_shoulder_roll_link"/>
      <origin xyz="-0.0 -0.0 -0.0" rpy="0.0 0.0 0.0"/>
   </joint>
   <link name="left_shoulder_yaw_link">
      <inertial>
         <origin xyz="0.010773 -0.002949 -0.072009" rpy="-0.2340491396282709 0.03511332089790531 1.5243028610703762"/>
         <mass value="0.734"/>
         <inertia ixx="0.00106187" iyy="0.00103217" izz="0.000400661" ixy="0" ixz="0" iyz="0"/>
      </inertial>
      <visual name="left_shoulder_yaw_link">
         <origin xyz="0.008049665594003904 -0.00420180564637434 -0.048209927243695244" rpy="-0.23785394371832946 0.13198198726331967 1.6702463147886015"/>
         <geometry>
            <mesh filename="package://bheema/unitree_g1/meshes/converted_left_shoulder_yaw_link_b2b2b2ff.obj"/>
         </geometry>
      </visual>
      <visual name="left_shoulder_yaw_link">
         <origin xyz="0.008049665594003904 -0.00420180564637434 -0.048209927243695244" rpy="-0.23785394371832946 0.13198198726331967 1.6702463147886015"/>
         <geometry>
            <mesh filename="package://bheema/unitree_g1/meshes/converted_left_shoulder_yaw_link_808080ff.obj"/>
         </geometry>
      </visual>
   </link>
   <link name="left_shoulder_yaw_joint_jointbody">
      <inertial>
         <origin xyz="0.0 0.0 0.0" rpy="0.0 0.0 0.0"/>
         <mass value="0.001"/>
         <inertia ixx="1e-09" iyy="1e-09" izz="1e-09" ixy="0" ixz="0" iyz="0"/>
      </inertial>
   </link>
   <joint type="revolute" name="left_shoulder_yaw_joint">
      <parent link="left_shoulder_roll_link"/>
      <child link="left_shoulder_yaw_joint_jointbody"/>
      <origin xyz="0.0 0.00624 -0.1032" rpy="0.0 0.0 0.0"/>
      <axis xyz="0.0 0.0 1.0"/>
      <limit lower="-2.618" upper="2.618" effort="100" velocity="100"/>
   </joint>
   <joint type="fixed" name="left_shoulder_yaw_joint_offset">
      <parent link="left_shoulder_yaw_joint_jointbody"/>
      <child link="left_shoulder_yaw_link"/>
      <origin xyz="-0.0 -0.0 -0.0" rpy="0.0 0.0 0.0"/>
   </joint>
   <link name="left_elbow_link">
      <inertial>
         <origin xyz="0.064956 0.004454 -0.010062" rpy="1.6830188159730721 -0.07256707188746447 1.1621215745061526"/>
         <mass value="0.6"/>
         <inertia ixx="0.000443035" iyy="0.000421612" izz="0.000259353" ixy="0" ixz="0" iyz="0"/>
      </inertial>
      <visual name="left_elbow_link">
         <origin xyz="0.053574244613676256 0.008583805643290808 -0.008537761350154273" rpy="1.6847179506028167 -0.05821775620593406 1.2367484910384527"/>
         <geometry>
            <mesh filename="package://bheema/unitree_g1/meshes/converted_left_elbow_link_b2b2b2ff.obj"/>
         </geometry>
      </visual>
      <visual name="left_elbow_link">
         <origin xyz="0.053574244613676256 0.008583805643290808 -0.008537761350154273" rpy="1.6847179506028167 -0.05821775620593406 1.2367484910384527"/>
         <geometry>
            <mesh filename="package://bheema/unitree_g1/meshes/converted_left_elbow_link_808080ff.obj"/>
         </geometry>
      </visual>
   </link>
   <link name="left_elbow_joint_jointbody">
      <inertial>
         <origin xyz="0.0 0.0 0.0" rpy="0.0 0.0 0.0"/>
         <mass value="0.001"/>
         <inertia ixx="1e-09" iyy="1e-09" izz="1e-09" ixy="0" ixz="0" iyz="0"/>
      </inertial>
   </link>
   <joint type="revolute" name="left_elbow_joint">
      <parent link="left_shoulder_yaw_link"/>
      <child link="left_elbow_joint_jointbody"/>
      <origin xyz="0.015783 0.0 -0.080518" rpy="0.0 0.0 0.0"/>
      <axis xyz="0.0 1.0 0.0"/>
      <limit lower="-1.0472" upper="2.0944" effort="100" velocity="100"/>
   </joint>
   <joint type="fixed" name="left_elbow_joint_offset">
      <parent link="left_elbow_joint_jointbody"/>
      <child link="left_elbow_link"/>
      <origin xyz="-0.0 -0.0 -0.0" rpy="0.0 0.0 0.0"/>
   </joint>
   <link name="left_wrist_roll_link">
      <inertial>
         <origin xyz="0.0171394 0.000537591 4.8864e-07" rpy="1.5457027398981822 -1.5697814832562638 -0.30387098421845293"/>
         <mass value="0.085445"/>
         <inertia ixx="5.48211e-05" iyy="4.96646e-05" izz="3.57798e-05" ixy="0" ixz="0" iyz="0"/>
      </inertial>
      <visual name="left_wrist_roll_link">
         <origin xyz="0.018657984394854582 5.9793423268075494e-06 -1.5958652824487767e-07" rpy="1.8145436634277998 -1.570603686945106 -0.2762879138730202"/>
         <geometry>
            <mesh filename="package://bheema/unitree_g1/meshes/converted_left_wrist_roll_link_b2b2b2ff.obj"/>
         </geometry>
      </visual>
      <visual name="left_wrist_roll_link">
         <origin xyz="0.018657984394854582 5.9793423268075494e-06 -1.5958652824487767e-07" rpy="1.8145436634277998 -1.570603686945106 -0.2762879138730202"/>
         <geometry>
            <mesh filename="package://bheema/unitree_g1/meshes/converted_left_wrist_roll_link_808080ff.obj"/>
         </geometry>
      </visual>
   </link>
   <link name="left_wrist_roll_joint_jointbody">
      <inertial>
         <origin xyz="0.0 0.0 0.0" rpy="0.0 0.0 0.0"/>
         <mass value="0.001"/>
         <inertia ixx="1e-09" iyy="1e-09" izz="1e-09" ixy="0" ixz="0" iyz="0"/>
      </inertial>
   </link>
   <joint type="revolute" name="left_wrist_roll_joint">
      <parent link="left_elbow_link"/>
      <child link="left_wrist_roll_joint_jointbody"/>
      <origin xyz="0.1 0.00188791 -0.01" rpy="0.0 0.0 0.0"/>
      <axis xyz="1.0 0.0 0.0"/>
      <limit lower="-1.97222" upper="1.97222" effort="100" velocity="100"/>
   </joint>
   <joint type="fixed" name="left_wrist_roll_joint_offset">
      <parent link="left_wrist_roll_joint_jointbody"/>
      <child link="left_wrist_roll_link"/>
      <origin xyz="-0.0 -0.0 -0.0" rpy="0.0 0.0 0.0"/>
   </joint>
   <link name="left_wrist_pitch_link">
      <inertial>
         <origin xyz="0.0229999 -0.00111685 -0.00111658" rpy="1.636448704066341 -0.7821401091177318 1.571080137027126"/>
         <mass value="0.48405"/>
         <inertia ixx="0.000430353" iyy="0.000429873" izz="0.000164648" ixy="0" ixz="0" iyz="0"/>
      </inertial>
      <visual name="left_wrist_pitch_link">
         <origin xyz="0.02300019707036519 -0.0005173613094355222 -0.000518381947122207" rpy="-1.6008824834192854 -0.8108809357715906 -1.5282434388651223"/>
         <geometry>
            <mesh filename="package://bheema/unitree_g1/meshes/converted_left_wrist_pitch_link_b2b2b2ff.obj"/>
         </geometry>
      </visual>
      <visual name="left_wrist_pitch_link">
         <origin xyz="0.02300019707036519 -0.0005173613094355222 -0.000518381947122207" rpy="-1.6008824834192854 -0.8108809357715906 -1.5282434388651223"/>
         <geometry>
            <mesh filename="package://bheema/unitree_g1/meshes/converted_left_wrist_pitch_link_808080ff.obj"/>
         </geometry>
      </visual>
   </link>
   <link name="left_wrist_pitch_joint_jointbody">
      <inertial>
         <origin xyz="0.0 0.0 0.0" rpy="0.0 0.0 0.0"/>
         <mass value="0.001"/>
         <inertia ixx="1e-09" iyy="1e-09" izz="1e-09" ixy="0" ixz="0" iyz="0"/>
      </inertial>
   </link>
   <joint type="revolute" name="left_wrist_pitch_joint">
      <parent link="left_wrist_roll_link"/>
      <child link="left_wrist_pitch_joint_jointbody"/>
      <origin xyz="0.038 0.0 0.0" rpy="0.0 0.0 0.0"/>
      <axis xyz="0.0 1.0 0.0"/>
      <limit lower="-1.61443" upper="1.61443" effort="100" velocity="100"/>
   </joint>
   <joint type="fixed" name="left_wrist_pitch_joint_offset">
      <parent link="left_wrist_pitch_joint_jointbody"/>
      <child link="left_wrist_pitch_link"/>
      <origin xyz="-0.0 -0.0 -0.0" rpy="0.0 0.0 0.0"/>
   </joint>
   <link name="left_wrist_yaw_link">
      <inertial>
         <origin xyz="0.0885506 0.00212216 -0.000374562" rpy="1.5853942288763119 0.0009136484846083981 1.6084122351038006"/>
         <mass value="0.457415"/>
         <inertia ixx="0.00105989" iyy="0.000895419" izz="0.000323842" ixy="0" ixz="0" iyz="0"/>
      </inertial>
      <visual name="left_wrist_yaw_link">
         <origin xyz="0.020643364729886877 0.0009027484895771055 2.863405704168882e-06" rpy="-0.038940958230515355 0.001778029011771709 1.6733310348097952"/>
         <geometry>
            <mesh filename="package://bheema/unitree_g1/meshes/converted_left_wrist_yaw_link_b2b2b2ff.obj"/>
         </geometry>
      </visual>
      <visual name="left_wrist_yaw_link">
         <origin xyz="0.020643364729886877 0.0009027484895771055 2.863405704168882e-06" rpy="-0.038940958230515355 0.001778029011771709 1.6733310348097952"/>
         <geometry>
            <mesh filename="package://bheema/unitree_g1/meshes/converted_left_wrist_yaw_link_808080ff.obj"/>
         </geometry>
      </visual>
      <visual name="left_hand_palm_link">
         <origin xyz="0.0838228789140701 0.004056139781855331 1.9648076160015474e-05" rpy="1.5689588524201783 -0.00029355426570565335 1.6267795997730503"/>
         <geometry>
            <mesh filename="package://bheema/unitree_g1/meshes/converted_left_hand_palm_link_b2b2b2ff.obj"/>
         </geometry>
      </visual>
      <visual name="left_hand_palm_link">
         <origin xyz="0.0838228789140701 0.004056139781855331 1.9648076160015474e-05" rpy="1.5689588524201783 -0.00029355426570565335 1.6267795997730503"/>
         <geometry>
            <mesh filename="package://bheema/unitree_g1/meshes/converted_left_hand_palm_link_808080ff.obj"/>
         </geometry>
      </visual>
   </link>
   <link name="left_wrist_yaw_joint_jointbody">
      <inertial>
         <origin xyz="0.0 0.0 0.0" rpy="0.0 0.0 0.0"/>
         <mass value="0.001"/>
         <inertia ixx="1e-09" iyy="1e-09" izz="1e-09" ixy="0" ixz="0" iyz="0"/>
      </inertial>
   </link>
   <joint type="revolute" name="left_wrist_yaw_joint">
      <parent link="left_wrist_pitch_link"/>
      <child link="left_wrist_yaw_joint_jointbody"/>
      <origin xyz="0.046 0.0 0.0" rpy="0.0 0.0 0.0"/>
      <axis xyz="0.0 0.0 1.0"/>
      <limit lower="-1.61443" upper="1.61443" effort="100" velocity="100"/>
   </joint>
   <joint type="fixed" name="left_wrist_yaw_joint_offset">
      <parent link="left_wrist_yaw_joint_jointbody"/>
      <child link="left_wrist_yaw_link"/>
      <origin xyz="-0.0 -0.0 -0.0" rpy="0.0 0.0 0.0"/>
   </joint>
   <link name="left_hand_thumb_0_link">
      <inertial>
         <origin xyz="-0.000884246 -0.00863407 0.000944293" rpy="2.4055424880961525 -1.2225640251740582 -0.7130451265504488"/>
         <mass value="0.0862366"/>
         <inertia ixx="1.6546e-05" iyy="1.60058e-05" izz="1.43741e-05" ixy="0" ixz="0" iyz="0"/>
      </inertial>
      <visual name="left_hand_thumb_0_link">
         <origin xyz="-0.000491862339801669 -0.013721147055190142 6.137514110301319e-19" rpy="1.6651308669454339 -1.5707963267948966 0.0"/>
         <geometry>
            <mesh filename="package://bheema/unitree_g1/meshes/converted_left_hand_thumb_0_link_b2b2b2ff.obj"/>
         </geometry>
      </visual>
      <visual name="left_hand_thumb_0_link">
         <origin xyz="-0.000491862339801669 -0.013721147055190142 6.137514110301319e-19" rpy="1.6651308669454339 -1.5707963267948966 0.0"/>
         <geometry>
            <mesh filename="package://bheema/unitree_g1/meshes/converted_left_hand_thumb_0_link_808080ff.obj"/>
         </geometry>
      </visual>
   </link>
   <link name="left_hand_thumb_0_joint_jointbody">
      <inertial>
         <origin xyz="0.0 0.0 0.0" rpy="0.0 0.0 0.0"/>
         <mass value="0.001"/>
         <inertia ixx="1e-09" iyy="1e-09" izz="1e-09" ixy="0" ixz="0" iyz="0"/>
      </inertial>
   </link>
   <joint type="revolute" name="left_hand_thumb_0_joint">
      <parent link="left_wrist_yaw_link"/>
      <child link="left_hand_thumb_0_joint_jointbody"/>
      <origin xyz="0.067 0.003 0.0" rpy="0.0 0.0 0.0"/>
      <axis xyz="0.0 1.0 0.0"/>
      <limit lower="-1.0472" upper="1.0472" effort="100" velocity="100"/>
   </joint>
   <joint type="fixed" name="left_hand_thumb_0_joint_offset">
      <parent link="left_hand_thumb_0_joint_jointbody"/>
      <child link="left_hand_thumb_0_link"/>
      <origin xyz="-0.0 -0.0 -0.0" rpy="0.0 0.0 0.0"/>
   </joint>
   <link name="left_hand_thumb_1_link">
      <inertial>
         <origin xyz="-0.000827888 -0.0354744 -0.0003809" rpy="1.6151358330393175 -0.35054913276603017 -0.08898830899064214"/>
         <mass value="0.0588507"/>
         <inertia ixx="1.28514e-05" iyy="1.22902e-05" izz="5.9666e-06" ixy="0" ixz="0" iyz="0"/>
      </inertial>
      <visual name="left_hand_thumb_1_link">
         <origin xyz="-0.0005196208062707493 -0.02973087578167297 -0.00039447612067983667" rpy="1.5455227053780893 -0.05863531363745067 -0.058704187153722276"/>
         <geometry>
            <mesh filename="package://bheema/unitree_g1/meshes/converted_left_hand_thumb_1_link_b2b2b2ff.obj"/>
         </geometry>
      </visual>
   </link>
   <link name="left_hand_thumb_1_joint_jointbody">
      <inertial>
         <origin xyz="0.0 0.0 0.0" rpy="0.0 0.0 0.0"/>
         <mass value="0.001"/>
         <inertia ixx="1e-09" iyy="1e-09" izz="1e-09" ixy="0" ixz="0" iyz="0"/>
      </inertial>
   </link>
   <joint type="revolute" name="left_hand_thumb_1_joint">
      <parent link="left_hand_thumb_0_link"/>
      <child link="left_hand_thumb_1_joint_jointbody"/>
      <origin xyz="-0.0025 -0.0193 0.0" rpy="0.0 0.0 0.0"/>
      <axis xyz="0.0 0.0 1.0"/>
      <limit lower="-0.724312" upper="1.0472" effort="100" velocity="100"/>
   </joint>
   <joint type="fixed" name="left_hand_thumb_1_joint_offset">
      <parent link="left_hand_thumb_1_joint_jointbody"/>
      <child link="left_hand_thumb_1_link"/>
      <origin xyz="-0.0 -0.0 -0.0" rpy="0.0 0.0 0.0"/>
   </joint>
   <link name="left_hand_thumb_2_link">
      <inertial>
         <origin xyz="-0.00171735 -0.0262819 0.000107789" rpy="1.5817730524934488 0.010653213492652469 -0.011030996055099718"/>
         <mass value="0.0203063"/>
         <inertia ixx="4.61314e-06" iyy="3.86645e-06" izz="1.53495e-06" ixy="0" ixz="0" iyz="0"/>
      </inertial>
      <visual name="left_hand_thumb_2_link">
         <origin xyz="-0.00020477239635855674 -0.02593452957629466 0.00022412485371993442" rpy="1.6074363861535836 4.542416809050209e-05 -0.0012391851046621438"/>
         <geometry>
            <mesh filename="package://bheema/unitree_g1/meshes/converted_left_hand_thumb_2_link_b2b2b2ff.obj"/>
         </geometry>
      </visual>
      <visual name="left_hand_thumb_2_link">
         <origin xyz="-0.00020477239635855674 -0.02593452957629466 0.00022412485371993442" rpy="1.6074363861535836 4.542416809050209e-05 -0.0012391851046621438"/>
         <geometry>
            <mesh filename="package://bheema/unitree_g1/meshes/converted_left_hand_thumb_2_link_808080ff.obj"/>
         </geometry>
      </visual>
   </link>
   <link name="left_hand_thumb_2_joint_jointbody">
      <inertial>
         <origin xyz="0.0 0.0 0.0" rpy="0.0 0.0 0.0"/>
         <mass value="0.001"/>
         <inertia ixx="1e-09" iyy="1e-09" izz="1e-09" ixy="0" ixz="0" iyz="0"/>
      </inertial>
   </link>
   <joint type="revolute" name="left_hand_thumb_2_joint">
      <parent link="left_hand_thumb_1_link"/>
      <child link="left_hand_thumb_2_joint_jointbody"/>
      <origin xyz="0.0 -0.0458 0.0" rpy="0.0 0.0 0.0"/>
      <axis xyz="0.0 0.0 1.0"/>
      <limit lower="0.0" upper="1.74533" effort="100" velocity="100"/>
   </joint>
   <joint type="fixed" name="left_hand_thumb_2_joint_offset">
      <parent link="left_hand_thumb_2_joint_jointbody"/>
      <child link="left_hand_thumb_2_link"/>
      <origin xyz="-0.0 -0.0 -0.0" rpy="0.0 0.0 0.0"/>
   </joint>
   <link name="left_hand_middle_0_link">
      <inertial>
         <origin xyz="0.0354744 0.000827888 0.0003809" rpy="1.5264572929964757 -0.35054921278533 1.659785715464094"/>
         <mass value="0.0588507"/>
         <inertia ixx="1.28514e-05" iyy="1.22902e-05" izz="5.9666e-06" ixy="0" ixz="0" iyz="0"/>
      </inertial>
      <visual name="left_hand_middle_0_link">
         <origin xyz="0.02973087578167297 0.0005196208062707493 0.00039447612067983667" rpy="1.5960699482117038 -0.05863531363745067 1.629500513948619"/>
         <geometry>
            <mesh filename="package://bheema/unitree_g1/meshes/converted_left_hand_middle_0_link_b2b2b2ff.obj"/>
         </geometry>
      </visual>
      <visual name="left_hand_middle_0_link">
         <origin xyz="0.02973087578167297 0.0005196208062707493 0.00039447612067983667" rpy="1.5960699482117038 -0.05863531363745067 1.629500513948619"/>
         <geometry>
            <mesh filename="package://bheema/unitree_g1/meshes/converted_left_hand_middle_0_link_808080ff.obj"/>
         </geometry>
      </visual>
   </link>
   <link name="left_hand_middle_0_joint_jointbody">
      <inertial>
         <origin xyz="0.0 0.0 0.0" rpy="0.0 0.0 0.0"/>
         <mass value="0.001"/>
         <inertia ixx="1e-09" iyy="1e-09" izz="1e-09" ixy="0" ixz="0" iyz="0"/>
      </inertial>
   </link>
   <joint type="revolute" name="left_hand_middle_0_joint">
      <parent link="left_wrist_yaw_link"/>
      <child link="left_hand_middle_0_joint_jointbody"/>
      <origin xyz="0.1192 0.0046 -0.0285" rpy="0.0 0.0 0.0"/>
      <axis xyz="0.0 0.0 1.0"/>
      <limit lower="-1.5708" upper="0.0" effort="100" velocity="100"/>
   </joint>
   <joint type="fixed" name="left_hand_middle_0_joint_offset">
      <parent link="left_hand_middle_0_joint_jointbody"/>
      <child link="left_hand_middle_0_link"/>
      <origin xyz="-0.0 -0.0 -0.0" rpy="0.0 0.0 0.0"/>
   </joint>
   <link name="left_hand_middle_1_link">
      <inertial>
         <origin xyz="0.0262819 0.00171735 -0.000107789" rpy="1.559819699036495 0.010651911255361135 1.5818272444613943"/>
         <mass value="0.0203063"/>
         <inertia ixx="4.61314e-06" iyy="3.86645e-06" izz="1.53495e-06" ixy="0" ixz="0" iyz="0"/>
      </inertial>
      <visual name="left_hand_middle_1_link">
         <origin xyz="0.02593452957629466 0.00020477239635855674 -0.00022412485371993442" rpy="1.5341562674362097 4.542416809050209e-05 1.5720355118995586"/>
         <geometry>
            <mesh filename="package://bheema/unitree_g1/meshes/converted_left_hand_middle_1_link_b2b2b2ff.obj"/>
         </geometry>
      </visual>
      <visual name="left_hand_middle_1_link">
         <origin xyz="0.02593452957629466 0.00020477239635855674 -0.00022412485371993442" rpy="1.5341562674362097 4.542416809050209e-05 1.5720355118995586"/>
         <geometry>
            <mesh filename="package://bheema/unitree_g1/meshes/converted_left_hand_middle_1_link_808080ff.obj"/>
         </geometry>
      </visual>
   </link>
   <link name="left_hand_middle_1_joint_jointbody">
      <inertial>
         <origin xyz="0.0 0.0 0.0" rpy="0.0 0.0 0.0"/>
         <mass value="0.001"/>
         <inertia ixx="1e-09" iyy="1e-09" izz="1e-09" ixy="0" ixz="0" iyz="0"/>
      </inertial>
   </link>
   <joint type="revolute" name="left_hand_middle_1_joint">
      <parent link="left_hand_middle_0_link"/>
      <child link="left_hand_middle_1_joint_jointbody"/>
      <origin xyz="0.0458 0.0 0.0" rpy="0.0 0.0 0.0"/>
      <axis xyz="0.0 0.0 1.0"/>
      <limit lower="-1.74533" upper="0.0" effort="100" velocity="100"/>
   </joint>
   <joint type="fixed" name="left_hand_middle_1_joint_offset">
      <parent link="left_hand_middle_1_joint_jointbody"/>
      <child link="left_hand_middle_1_link"/>
      <origin xyz="-0.0 -0.0 -0.0" rpy="0.0 0.0 0.0"/>
   </joint>
   <link name="left_hand_index_0_link">
      <inertial>
         <origin xyz="0.0354744 0.000827888 0.0003809" rpy="1.5264572929964757 -0.35054921278533 1.659785715464094"/>
         <mass value="0.0588507"/>
         <inertia ixx="1.28514e-05" iyy="1.22902e-05" izz="5.9666e-06" ixy="0" ixz="0" iyz="0"/>
      </inertial>
      <visual name="left_hand_index_0_link">
         <origin xyz="0.02973087578167297 0.0005196208062707493 0.00039447612067983667" rpy="1.5960699482117038 -0.05863531363745067 1.629500513948619"/>
         <geometry>
            <mesh filename="package://bheema/unitree_g1/meshes/converted_left_hand_index_0_link_b2b2b2ff.obj"/>
         </geometry>
      </visual>
      <visual name="left_hand_index_0_link">
         <origin xyz="0.02973087578167297 0.0005196208062707493 0.00039447612067983667" rpy="1.5960699482117038 -0.05863531363745067 1.629500513948619"/>
         <geometry>
            <mesh filename="package://bheema/unitree_g1/meshes/converted_left_hand_index_0_link_808080ff.obj"/>
         </geometry>
      </visual>
   </link>
   <link name="left_hand_index_0_joint_jointbody">
      <inertial>
         <origin xyz="0.0 0.0 0.0" rpy="0.0 0.0 0.0"/>
         <mass value="0.001"/>
         <inertia ixx="1e-09" iyy="1e-09" izz="1e-09" ixy="0" ixz="0" iyz="0"/>
      </inertial>
   </link>
   <joint type="revolute" name="left_hand_index_0_joint">
      <parent link="left_wrist_yaw_link"/>
      <child link="left_hand_index_0_joint_jointbody"/>
      <origin xyz="0.1192 0.0046 0.0285" rpy="0.0 0.0 0.0"/>
      <axis xyz="0.0 0.0 1.0"/>
      <limit lower="-1.5708" upper="0.0" effort="100" velocity="100"/>
   </joint>
   <joint type="fixed" name="left_hand_index_0_joint_offset">
      <parent link="left_hand_index_0_joint_jointbody"/>
      <child link="left_hand_index_0_link"/>
      <origin xyz="-0.0 -0.0 -0.0" rpy="0.0 0.0 0.0"/>
   </joint>
   <link name="left_hand_index_1_link">
      <inertial>
         <origin xyz="0.0262819 0.00171735 -0.000107789" rpy="1.559819699036495 0.010651911255361135 1.5818272444613943"/>
         <mass value="0.0203063"/>
         <inertia ixx="4.61314e-06" iyy="3.86645e-06" izz="1.53495e-06" ixy="0" ixz="0" iyz="0"/>
      </inertial>
      <visual name="left_hand_index_1_link">
         <origin xyz="0.02593452957629466 0.00020477239635855674 -0.00022412485371993442" rpy="1.5341562674362097 4.542416809050209e-05 1.5720355118995586"/>
         <geometry>
            <mesh filename="package://bheema/unitree_g1/meshes/converted_left_hand_index_1_link_b2b2b2ff.obj"/>
         </geometry>
      </visual>
      <visual name="left_hand_index_1_link">
         <origin xyz="0.02593452957629466 0.00020477239635855674 -0.00022412485371993442" rpy="1.5341562674362097 4.542416809050209e-05 1.5720355118995586"/>
         <geometry>
            <mesh filename="package://bheema/unitree_g1/meshes/converted_left_hand_index_1_link_808080ff.obj"/>
         </geometry>
      </visual>
   </link>
   <link name="left_hand_index_1_joint_jointbody">
      <inertial>
         <origin xyz="0.0 0.0 0.0" rpy="0.0 0.0 0.0"/>
         <mass value="0.001"/>
         <inertia ixx="1e-09" iyy="1e-09" izz="1e-09" ixy="0" ixz="0" iyz="0"/>
      </inertial>
   </link>
   <joint type="revolute" name="left_hand_index_1_joint">
      <parent link="left_hand_index_0_link"/>
      <child link="left_hand_index_1_joint_jointbody"/>
      <origin xyz="0.0458 0.0 0.0" rpy="0.0 0.0 0.0"/>
      <axis xyz="0.0 0.0 1.0"/>
      <limit lower="-1.74533" upper="0.0" effort="100" velocity="100"/>
   </joint>
   <joint type="fixed" name="left_hand_index_1_joint_offset">
      <parent link="left_hand_index_1_joint_jointbody"/>
      <child link="left_hand_index_1_link"/>
      <origin xyz="-0.0 -0.0 -0.0" rpy="0.0 0.0 0.0"/>
   </joint>
   <link name="right_shoulder_pitch_link">
      <inertial>
         <origin xyz="0.0 -0.035892 -0.011628" rpy="-0.4983488351736898 0.46079162371774673 1.409519751258105"/>
         <mass value="0.718"/>
         <inertia ixx="0.000465864" iyy="0.000432842" izz="0.000406394" ixy="0" ixz="0" iyz="0"/>
      </inertial>
      <visual name="right_shoulder_pitch_link">
         <origin xyz="-2.4137104255368755e-05 -0.0345432594895927 -0.008909147962374762" rpy="0.029489658745679548 0.5899063567170857 1.638187772345466"/>
         <geometry>
            <mesh filename="package://bheema/unitree_g1/meshes/converted_right_shoulder_pitch_link_b2b2b2ff.obj"/>
         </geometry>
      </visual>
   </link>
   <link name="right_shoulder_pitch_joint_jointbody">
      <inertial>
         <origin xyz="0.0 0.0 0.0" rpy="0.0 0.0 0.0"/>
         <mass value="0.001"/>
         <inertia ixx="1e-09" iyy="1e-09" izz="1e-09" ixy="0" ixz="0" iyz="0"/>
      </inertial>
   </link>
   <joint type="revolute" name="right_shoulder_pitch_joint">
      <parent link="torso_link"/>
      <child link="right_shoulder_pitch_joint_jointbody"/>
      <origin xyz="0.0039563 -0.10021 0.24778" rpy="-0.2793090626390551 5.4948898537077184e-05 0.00019158997789023302"/>
      <axis xyz="0.0 1.0 0.0"/>
      <limit lower="-3.0892" upper="2.6704" effort="100" velocity="100"/>
   </joint>
   <joint type="fixed" name="right_shoulder_pitch_joint_offset">
      <parent link="right_shoulder_pitch_joint_jointbody"/>
      <child link="right_shoulder_pitch_link"/>
      <origin xyz="-0.0 -0.0 -0.0" rpy="0.0 0.0 0.0"/>
   </joint>
   <link name="right_shoulder_roll_link">
      <inertial>
         <origin xyz="-0.000227 -0.00727 -0.063243" rpy="-0.03765901158544349 -0.018004551792828227 1.5550832287919003"/>
         <mass value="0.643"/>
         <inertia ixx="0.000691311" iyy="0.000618011" izz="0.000388977" ixy="0" ixz="0" iyz="0"/>
      </inertial>
      <visual name="right_shoulder_roll_link">
         <origin xyz="3.0647723212395196e-05 -0.007746894558775755 -0.03750597545142516" rpy="0.0034383267276915097 0.07940700891787733 1.5713375585975289"/>
         <geometry>
            <mesh filename="package://bheema/unitree_g1/meshes/converted_right_shoulder_roll_link_b2b2b2ff.obj"/>
         </geometry>
      </visual>
   </link>
   <link name="right_shoulder_roll_joint_jointbody">
      <inertial>
         <origin xyz="0.0 0.0 0.0" rpy="0.0 0.0 0.0"/>
         <mass value="0.001"/>
         <inertia ixx="1e-09" iyy="1e-09" izz="1e-09" ixy="0" ixz="0" iyz="0"/>
      </inertial>
   </link>
   <joint type="revolute" name="right_shoulder_roll_joint">
      <parent link="right_shoulder_pitch_link"/>
      <child link="right_shoulder_roll_joint_jointbody"/>
      <origin xyz="0.0 -0.038 -0.013831" rpy="0.2792505189613739 0.0 0.0"/>
      <axis xyz="1.0 0.0 0.0"/>
      <limit lower="-2.2515" upper="1.5882" effort="100" velocity="100"/>
   </joint>
   <joint type="fixed" name="right_shoulder_roll_joint_offset">
      <parent link="right_shoulder_roll_joint_jointbody"/>
      <child link="right_shoulder_roll_link"/>
      <origin xyz="-0.0 -0.0 -0.0" rpy="0.0 0.0 0.0"/>
   </joint>
   <link name="right_shoulder_yaw_link">
      <inertial>
         <origin xyz="0.010773 0.002949 -0.072009" rpy="-0.23404913962827079 -0.03511332089790531 1.6172897925194172"/>
         <mass value="0.734"/>
         <inertia ixx="0.00106187" iyy="0.00103217" izz="0.000400661" ixy="0" ixz="0" iyz="0"/>
      </inertial>
      <visual name="right_shoulder_yaw_link">
         <origin xyz="0.00804956885105232 0.00420282487216018 -0.04821007683406935" rpy="-0.2379258414692521 -0.131909096933281 1.471453582750537"/>
         <geometry>
            <mesh filename="package://bheema/unitree_g1/meshes/converted_right_shoulder_yaw_link_b2b2b2ff.obj"/>
         </geometry>
      </visual>
      <visual name="right_shoulder_yaw_link">
         <origin xyz="0.00804956885105232 0.00420282487216018 -0.04821007683406935" rpy="-0.2379258414692521 -0.131909096933281 1.471453582750537"/>
         <geometry>
            <mesh filename="package://bheema/unitree_g1/meshes/converted_right_shoulder_yaw_link_808080ff.obj"/>
         </geometry>
      </visual>
   </link>
   <link name="right_shoulder_yaw_joint_jointbody">
      <inertial>
         <origin xyz="0.0 0.0 0.0" rpy="0.0 0.0 0.0"/>
         <mass value="0.001"/>
         <inertia ixx="1e-09" iyy="1e-09" izz="1e-09" ixy="0" ixz="0" iyz="0"/>
      </inertial>
   </link>
   <joint type="revolute" name="right_shoulder_yaw_joint">
      <parent link="right_shoulder_roll_link"/>
      <child link="right_shoulder_yaw_joint_jointbody"/>
      <origin xyz="0.0 -0.00624 -0.1032" rpy="0.0 0.0 0.0"/>
      <axis xyz="0.0 0.0 1.0"/>
      <limit lower="-2.618" upper="2.618" effort="100" velocity="100"/>
   </joint>
   <joint type="fixed" name="right_shoulder_yaw_joint_offset">
      <parent link="right_shoulder_yaw_joint_jointbody"/>
      <child link="right_shoulder_yaw_link"/>
      <origin xyz="-0.0 -0.0 -0.0" rpy="0.0 0.0 0.0"/>
   </joint>
   <link name="right_elbow_link">
      <inertial>
         <origin xyz="0.064956 -0.004454 -0.010062" rpy="1.683018815973072 0.07256707188746425 1.9794710790836403"/>
         <mass value="0.6"/>
         <inertia ixx="0.000443035" iyy="0.000421612" izz="0.000259353" ixy="0" ixz="0" iyz="0"/>
      </inertial>
      <visual name="right_elbow_link">
         <origin xyz="0.05357441187591211 -0.008582284246788056 -0.008536567848057683" rpy="1.684727046357678 0.05830849866102805 1.9048205303534707"/>
         <geometry>
            <mesh filename="package://bheema/unitree_g1/meshes/converted_right_elbow_link_b2b2b2ff.obj"/>
         </geometry>
      </visual>
      <visual name="right_elbow_link">
         <origin xyz="0.05357441187591211 -0.008582284246788056 -0.008536567848057683" rpy="1.684727046357678 0.05830849866102805 1.9048205303534707"/>
         <geometry>
            <mesh filename="package://bheema/unitree_g1/meshes/converted_right_elbow_link_808080ff.obj"/>
         </geometry>
      </visual>
   </link>
   <link name="right_elbow_joint_jointbody">
      <inertial>
         <origin xyz="0.0 0.0 0.0" rpy="0.0 0.0 0.0"/>
         <mass value="0.001"/>
         <inertia ixx="1e-09" iyy="1e-09" izz="1e-09" ixy="0" ixz="0" iyz="0"/>
      </inertial>
   </link>
   <joint type="revolute" name="right_elbow_joint">
      <parent link="right_shoulder_yaw_link"/>
      <child link="right_elbow_joint_jointbody"/>
      <origin xyz="0.015783 0.0 -0.080518" rpy="0.0 0.0 0.0"/>
      <axis xyz="0.0 1.0 0.0"/>
      <limit lower="-1.0472" upper="2.0944" effort="100" velocity="100"/>
   </joint>
   <joint type="fixed" name="right_elbow_joint_offset">
      <parent link="right_elbow_joint_jointbody"/>
      <child link="right_elbow_link"/>
      <origin xyz="-0.0 -0.0 -0.0" rpy="0.0 0.0 0.0"/>
   </joint>
   <link name="right_wrist_roll_link">
      <inertial>
         <origin xyz="0.0171394 -0.000537591 4.8864e-07" rpy="1.595889913691611 -1.5697814832562638 0.30387098421845304"/>
         <mass value="0.085445"/>
         <inertia ixx="5.48211e-05" iyy="4.96646e-05" izz="3.57798e-05" ixy="0" ixz="0" iyz="0"/>
      </inertial>
      <visual name="right_wrist_roll_link">
         <origin xyz="0.018657941307464523 -5.957828778852661e-06 -4.83245646150392e-07" rpy="1.5707963267958835 -1.5706553356919561 0.0325626474150873"/>
         <geometry>
            <mesh filename="package://bheema/unitree_g1/meshes/converted_right_wrist_roll_link_b2b2b2ff.obj"/>
         </geometry>
      </visual>
      <visual name="right_wrist_roll_link">
         <origin xyz="0.018657941307464523 -5.957828778852661e-06 -4.83245646150392e-07" rpy="1.5707963267958835 -1.5706553356919561 0.0325626474150873"/>
         <geometry>
            <mesh filename="package://bheema/unitree_g1/meshes/converted_right_wrist_roll_link_808080ff.obj"/>
         </geometry>
      </visual>
   </link>
   <link name="right_wrist_roll_joint_jointbody">
      <inertial>
         <origin xyz="0.0 0.0 0.0" rpy="0.0 0.0 0.0"/>
         <mass value="0.001"/>
         <inertia ixx="1e-09" iyy="1e-09" izz="1e-09" ixy="0" ixz="0" iyz="0"/>
      </inertial>
   </link>
   <joint type="revolute" name="right_wrist_roll_joint">
      <parent link="right_elbow_link"/>
      <child link="right_wrist_roll_joint_jointbody"/>
      <origin xyz="0.1 -0.00188791 -0.01" rpy="0.0 0.0 0.0"/>
      <axis xyz="1.0 0.0 0.0"/>
      <limit lower="-1.97222" upper="1.97222" effort="100" velocity="100"/>
   </joint>
   <joint type="fixed" name="right_wrist_roll_joint_offset">
      <parent link="right_wrist_roll_joint_jointbody"/>
      <child link="right_wrist_roll_link"/>
      <origin xyz="-0.0 -0.0 -0.0" rpy="0.0 0.0 0.0"/>
   </joint>
   <link name="right_wrist_pitch_link">
      <inertial>
         <origin xyz="0.0229999 0.00111685 -0.00111658" rpy="1.6364487040663414 0.7821401091177322 1.5705125165626677"/>
         <mass value="0.48405"/>
         <inertia ixx="0.000430353" iyy="0.000429873" izz="0.000164648" ixy="0" ixz="0" iyz="0"/>
      </inertial>
      <visual name="right_wrist_pitch_link">
         <origin xyz="0.022999880367268993 0.0005172208304745039 -0.0005182067564729859" rpy="1.600189111072446 -0.7879128559570059 1.5292083470467561"/>
         <geometry>
            <mesh filename="package://bheema/unitree_g1/meshes/converted_right_wrist_pitch_link_b2b2b2ff.obj"/>
         </geometry>
      </visual>
      <visual name="right_wrist_pitch_link">
         <origin xyz="0.022999880367268993 0.0005172208304745039 -0.0005182067564729859" rpy="1.600189111072446 -0.7879128559570059 1.5292083470467561"/>
         <geometry>
            <mesh filename="package://bheema/unitree_g1/meshes/converted_right_wrist_pitch_link_808080ff.obj"/>
         </geometry>
      </visual>
   </link>
   <link name="right_wrist_pitch_joint_jointbody">
      <inertial>
         <origin xyz="0.0 0.0 0.0" rpy="0.0 0.0 0.0"/>
         <mass value="0.001"/>
         <inertia ixx="1e-09" iyy="1e-09" izz="1e-09" ixy="0" ixz="0" iyz="0"/>
      </inertial>
   </link>
   <joint type="revolute" name="right_wrist_pitch_joint">
      <parent link="right_wrist_roll_link"/>
      <child link="right_wrist_pitch_joint_jointbody"/>
      <origin xyz="0.038 0.0 0.0" rpy="0.0 0.0 0.0"/>
      <axis xyz="0.0 1.0 0.0"/>
      <limit lower="-1.61443" upper="1.61443" effort="100" velocity="100"/>
   </joint>
   <joint type="fixed" name="right_wrist_pitch_joint_offset">
      <parent link="right_wrist_pitch_joint_jointbody"/>
      <child link="right_wrist_pitch_link"/>
      <origin xyz="-0.0 -0.0 -0.0" rpy="0.0 0.0 0.0"/>
   </joint>
   <link name="right_wrist_yaw_link">
      <inertial>
         <origin xyz="0.0885506 -0.00212216 -0.000374562" rpy="1.5853942288763119 -0.000913648484608176 1.5331804184859925"/>
         <mass value="0.457415"/>
         <inertia ixx="0.00105989" iyy="0.000895419" izz="0.000323842" ixy="0" ixz="0" iyz="0"/>
      </inertial>
      <visual name="right_wrist_yaw_link">
         <origin xyz="0.020642202624980278 -0.0009024964060801943 4.787797910695187e-06" rpy="-0.03919436741674498 -0.0017808560332783774 1.4683311967879622"/>
         <geometry>
            <mesh filename="package://bheema/unitree_g1/meshes/converted_right_wrist_yaw_link_b2b2b2ff.obj"/>
         </geometry>
      </visual>
      <visual name="right_wrist_yaw_link">
         <origin xyz="0.020642202624980278 -0.0009024964060801943 4.787797910695187e-06" rpy="-0.03919436741674498 -0.0017808560332783774 1.4683311967879622"/>
         <geometry>
            <mesh filename="package://bheema/unitree_g1/meshes/converted_right_wrist_yaw_link_808080ff.obj"/>
         </geometry>
      </visual>
      <visual name="right_hand_palm_link">
         <origin xyz="0.08382288875329008 -0.004056140630289747 -1.9648076013324923e-05" rpy="1.5726337651224702 -0.0002935540932460512 1.514813040931026"/>
         <geometry>
            <mesh filename="package://bheema/unitree_g1/meshes/converted_right_hand_palm_link_b2b2b2ff.obj"/>
         </geometry>
      </visual>
      <visual name="right_hand_palm_link">
         <origin xyz="0.08382288875329008 -0.004056140630289747 -1.9648076013324923e-05" rpy="1.5726337651224702 -0.0002935540932460512 1.514813040931026"/>
         <geometry>
            <mesh filename="package://bheema/unitree_g1/meshes/converted_right_hand_palm_link_808080ff.obj"/>
         </geometry>
      </visual>
   </link>
   <link name="right_wrist_yaw_joint_jointbody">
      <inertial>
         <origin xyz="0.0 0.0 0.0" rpy="0.0 0.0 0.0"/>
         <mass value="0.001"/>
         <inertia ixx="1e-09" iyy="1e-09" izz="1e-09" ixy="0" ixz="0" iyz="0"/>
      </inertial>
   </link>
   <joint type="revolute" name="right_wrist_yaw_joint">
      <parent link="right_wrist_pitch_link"/>
      <child link="right_wrist_yaw_joint_jointbody"/>
      <origin xyz="0.046 0.0 0.0" rpy="0.0 0.0 0.0"/>
      <axis xyz="0.0 0.0 1.0"/>
      <limit lower="-1.61443" upper="1.61443" effort="100" velocity="100"/>
   </joint>
   <joint type="fixed" name="right_wrist_yaw_joint_offset">
      <parent link="right_wrist_yaw_joint_jointbody"/>
      <child link="right_wrist_yaw_link"/>
      <origin xyz="-0.0 -0.0 -0.0" rpy="0.0 0.0 0.0"/>
   </joint>
   <link name="right_hand_thumb_0_link">
      <inertial>
         <origin xyz="-0.000884246 0.00863407 0.000944293" rpy="0.7360501654936406 -1.2225640251740584 0.7130451265504488"/>
         <mass value="0.0862366"/>
         <inertia ixx="1.6546e-05" iyy="1.60058e-05" izz="1.43741e-05" ixy="0" ixz="0" iyz="0"/>
      </inertial>
      <visual name="right_hand_thumb_0_link">
         <origin xyz="-0.000491862339801669 0.013721147055190142 -6.137514110301319e-19" rpy="1.4764617866443595 -1.5707963267948966 0.0"/>
         <geometry>
            <mesh filename="package://bheema/unitree_g1/meshes/converted_right_hand_thumb_0_link_b2b2b2ff.obj"/>
         </geometry>
      </visual>
      <visual name="right_hand_thumb_0_link">
         <origin xyz="-0.000491862339801669 0.013721147055190142 -6.137514110301319e-19" rpy="1.4764617866443595 -1.5707963267948966 0.0"/>
         <geometry>
            <mesh filename="package://bheema/unitree_g1/meshes/converted_right_hand_thumb_0_link_808080ff.obj"/>
         </geometry>
      </visual>
   </link>
   <link name="right_hand_thumb_0_joint_jointbody">
      <inertial>
         <origin xyz="0.0 0.0 0.0" rpy="0.0 0.0 0.0"/>
         <mass value="0.001"/>
         <inertia ixx="1e-09" iyy="1e-09" izz="1e-09" ixy="0" ixz="0" iyz="0"/>
      </inertial>
   </link>
   <joint type="revolute" name="right_hand_thumb_0_joint">
      <parent link="right_wrist_yaw_link"/>
      <child link="right_hand_thumb_0_joint_jointbody"/>
      <origin xyz="0.067 -0.003 0.0" rpy="0.0 0.0 0.0"/>
      <axis xyz="0.0 1.0 0.0"/>
      <limit lower="-1.0472" upper="1.0472" effort="100" velocity="100"/>
   </joint>
   <joint type="fixed" name="right_hand_thumb_0_joint_offset">
      <parent link="right_hand_thumb_0_joint_jointbody"/>
      <child link="right_hand_thumb_0_link"/>
      <origin xyz="-0.0 -0.0 -0.0" rpy="0.0 0.0 0.0"/>
   </joint>
   <link name="right_hand_thumb_1_link">
      <inertial>
         <origin xyz="-0.000827888 0.0354744 -0.0003809" rpy="1.5264568205504756 -0.35054913276603017 0.08898830899064214"/>
         <mass value="0.0588507"/>
         <inertia ixx="1.28514e-05" iyy="1.22902e-05" izz="5.9666e-06" ixy="0" ixz="0" iyz="0"/>
      </inertial>
      <visual name="right_hand_thumb_1_link">
         <origin xyz="-0.0005196208062707493 0.02973087578167297 0.00039447612067983667" rpy="1.5455227053780893 0.05863531363745089 0.058704187153722276"/>
         <geometry>
            <mesh filename="package://bheema/unitree_g1/meshes/converted_right_hand_thumb_1_link_b2b2b2ff.obj"/>
         </geometry>
      </visual>
   </link>
   <link name="right_hand_thumb_1_joint_jointbody">
      <inertial>
         <origin xyz="0.0 0.0 0.0" rpy="0.0 0.0 0.0"/>
         <mass value="0.001"/>
         <inertia ixx="1e-09" iyy="1e-09" izz="1e-09" ixy="0" ixz="0" iyz="0"/>
      </inertial>
   </link>
   <joint type="revolute" name="right_hand_thumb_1_joint">
      <parent link="right_hand_thumb_0_link"/>
      <child link="right_hand_thumb_1_joint_jointbody"/>
      <origin xyz="-0.0025 0.0193 0.0" rpy="0.0 0.0 0.0"/>
      <axis xyz="0.0 0.0 1.0"/>
      <limit lower="-1.0472" upper="0.724312" effort="100" velocity="100"/>
   </joint>
   <joint type="fixed" name="right_hand_thumb_1_joint_offset">
      <parent link="right_hand_thumb_1_joint_jointbody"/>
      <child link="right_hand_thumb_1_link"/>
      <origin xyz="-0.0 -0.0 -0.0" rpy="0.0 0.0 0.0"/>
   </joint>
   <link name="right_hand_thumb_2_link">
      <inertial>
         <origin xyz="-0.00171735 0.0262819 0.000107789" rpy="1.5598196010963445 0.010653213492652469 0.011030996055099607"/>
         <mass value="0.0203063"/>
         <inertia ixx="4.61314e-06" iyy="3.86645e-06" izz="1.53495e-06" ixy="0" ixz="0" iyz="0"/>
      </inertial>
      <visual name="right_hand_thumb_2_link">
         <origin xyz="-0.00020477239635855674 0.02593452957629466 -0.00022412485371993442" rpy="1.6074363861535836 -4.542416809050209e-05 0.0012391851046621438"/>
         <geometry>
            <mesh filename="package://bheema/unitree_g1/meshes/converted_right_hand_thumb_2_link_b2b2b2ff.obj"/>
         </geometry>
      </visual>
      <visual name="right_hand_thumb_2_link">
         <origin xyz="-0.00020477239635855674 0.02593452957629466 -0.00022412485371993442" rpy="1.6074363861535836 -4.542416809050209e-05 0.0012391851046621438"/>
         <geometry>
            <mesh filename="package://bheema/unitree_g1/meshes/converted_right_hand_thumb_2_link_808080ff.obj"/>
         </geometry>
      </visual>
   </link>
   <link name="right_hand_thumb_2_joint_jointbody">
      <inertial>
         <origin xyz="0.0 0.0 0.0" rpy="0.0 0.0 0.0"/>
         <mass value="0.001"/>
         <inertia ixx="1e-09" iyy="1e-09" izz="1e-09" ixy="0" ixz="0" iyz="0"/>
      </inertial>
   </link>
   <joint type="revolute" name="right_hand_thumb_2_joint">
      <parent link="right_hand_thumb_1_link"/>
      <child link="right_hand_thumb_2_joint_jointbody"/>
      <origin xyz="0.0 0.0458 0.0" rpy="0.0 0.0 0.0"/>
      <axis xyz="0.0 0.0 1.0"/>
      <limit lower="-1.74533" upper="0.0" effort="100" velocity="100"/>
   </joint>
   <joint type="fixed" name="right_hand_thumb_2_joint_offset">
      <parent link="right_hand_thumb_2_joint_jointbody"/>
      <child link="right_hand_thumb_2_link"/>
      <origin xyz="-0.0 -0.0 -0.0" rpy="0.0 0.0 0.0"/>
   </joint>
   <link name="right_hand_middle_0_link">
      <inertial>
         <origin xyz="0.0354744 -0.000827888 0.0003809" rpy="1.5264572929964757 0.35054921278533 1.4818069381256995"/>
         <mass value="0.0588507"/>
         <inertia ixx="1.28514e-05" iyy="1.22902e-05" izz="5.9666e-06" ixy="0" ixz="0" iyz="0"/>
      </inertial>
      <visual name="right_hand_middle_0_link">
         <origin xyz="0.02973087578167297 -0.0005196208062707493 -0.00039447612067983667" rpy="1.5455227053780896 -0.05863531363745067 1.5120921396411744"/>
         <geometry>
            <mesh filename="package://bheema/unitree_g1/meshes/converted_right_hand_middle_0_link_b2b2b2ff.obj"/>
         </geometry>
      </visual>
      <visual name="right_hand_middle_0_link">
         <origin xyz="0.02973087578167297 -0.0005196208062707493 -0.00039447612067983667" rpy="1.5455227053780896 -0.05863531363745067 1.5120921396411744"/>
         <geometry>
            <mesh filename="package://bheema/unitree_g1/meshes/converted_right_hand_middle_0_link_808080ff.obj"/>
         </geometry>
      </visual>
   </link>
   <link name="right_hand_middle_0_joint_jointbody">
      <inertial>
         <origin xyz="0.0 0.0 0.0" rpy="0.0 0.0 0.0"/>
         <mass value="0.001"/>
         <inertia ixx="1e-09" iyy="1e-09" izz="1e-09" ixy="0" ixz="0" iyz="0"/>
      </inertial>
   </link>
   <joint type="revolute" name="right_hand_middle_0_joint">
      <parent link="right_wrist_yaw_link"/>
      <child link="right_hand_middle_0_joint_jointbody"/>
      <origin xyz="0.1192 -0.0046 -0.0285" rpy="0.0 0.0 0.0"/>
      <axis xyz="0.0 0.0 1.0"/>
      <limit lower="0.0" upper="1.5708" effort="100" velocity="100"/>
   </joint>
   <joint type="fixed" name="right_hand_middle_0_joint_offset">
      <parent link="right_hand_middle_0_joint_jointbody"/>
      <child link="right_hand_middle_0_link"/>
      <origin xyz="-0.0 -0.0 -0.0" rpy="0.0 0.0 0.0"/>
   </joint>
   <link name="right_hand_middle_1_link">
      <inertial>
         <origin xyz="0.0262819 -0.00171735 -0.000107789" rpy="1.559819699036495 -0.010651911255361135 1.5597654091283988"/>
         <mass value="0.0203063"/>
         <inertia ixx="4.61314e-06" iyy="3.86645e-06" izz="1.53495e-06" ixy="0" ixz="0" iyz="0"/>
      </inertial>
      <visual name="right_hand_middle_1_link">
         <origin xyz="0.02593452957629466 -0.00020477239635855674 0.00022412485371993442" rpy="1.6074363861535836 4.542416809050209e-05 1.5695571416902347"/>
         <geometry>
            <mesh filename="package://bheema/unitree_g1/meshes/converted_right_hand_middle_1_link_b2b2b2ff.obj"/>
         </geometry>
      </visual>
      <visual name="right_hand_middle_1_link">
         <origin xyz="0.02593452957629466 -0.00020477239635855674 0.00022412485371993442" rpy="1.6074363861535836 4.542416809050209e-05 1.5695571416902347"/>
         <geometry>
            <mesh filename="package://bheema/unitree_g1/meshes/converted_right_hand_middle_1_link_808080ff.obj"/>
         </geometry>
      </visual>
   </link>
   <link name="right_hand_middle_1_joint_jointbody">
      <inertial>
         <origin xyz="0.0 0.0 0.0" rpy="0.0 0.0 0.0"/>
         <mass value="0.001"/>
         <inertia ixx="1e-09" iyy="1e-09" izz="1e-09" ixy="0" ixz="0" iyz="0"/>
      </inertial>
   </link>
   <joint type="revolute" name="right_hand_middle_1_joint">
      <parent link="right_hand_middle_0_link"/>
      <child link="right_hand_middle_1_joint_jointbody"/>
      <origin xyz="0.0458 0.0 0.0" rpy="0.0 0.0 0.0"/>
      <axis xyz="0.0 0.0 1.0"/>
      <limit lower="0.0" upper="1.74533" effort="100" velocity="100"/>
   </joint>
   <joint type="fixed" name="right_hand_middle_1_joint_offset">
      <parent link="right_hand_middle_1_joint_jointbody"/>
      <child link="right_hand_middle_1_link"/>
      <origin xyz="-0.0 -0.0 -0.0" rpy="0.0 0.0 0.0"/>
   </joint>
   <link name="right_hand_index_0_link">
      <inertial>
         <origin xyz="0.0354744 -0.000827888 0.0003809" rpy="1.5264572929964757 0.35054921278533 1.4818069381256995"/>
         <mass value="0.0588507"/>
         <inertia ixx="1.28514e-05" iyy="1.22902e-05" izz="5.9666e-06" ixy="0" ixz="0" iyz="0"/>
      </inertial>
      <visual name="right_hand_index_0_link">
         <origin xyz="0.02973087578167297 -0.0005196208062707493 -0.00039447612067983667" rpy="1.5455227053780896 -0.05863531363745067 1.5120921396411744"/>
         <geometry>
            <mesh filename="package://bheema/unitree_g1/meshes/converted_right_hand_index_0_link_b2b2b2ff.obj"/>
         </geometry>
      </visual>
      <visual name="right_hand_index_0_link">
         <origin xyz="0.02973087578167297 -0.0005196208062707493 -0.00039447612067983667" rpy="1.5455227053780896 -0.05863531363745067 1.5120921396411744"/>
         <geometry>
            <mesh filename="package://bheema/unitree_g1/meshes/converted_right_hand_index_0_link_808080ff.obj"/>
         </geometry>
      </visual>
   </link>
   <link name="right_hand_index_0_joint_jointbody">
      <inertial>
         <origin xyz="0.0 0.0 0.0" rpy="0.0 0.0 0.0"/>
         <mass value="0.001"/>
         <inertia ixx="1e-09" iyy="1e-09" izz="1e-09" ixy="0" ixz="0" iyz="0"/>
      </inertial>
   </link>
   <joint type="revolute" name="right_hand_index_0_joint">
      <parent link="right_wrist_yaw_link"/>
      <child link="right_hand_index_0_joint_jointbody"/>
      <origin xyz="0.1192 -0.0046 0.0285" rpy="0.0 0.0 0.0"/>
      <axis xyz="0.0 0.0 1.0"/>
      <limit lower="0.0" upper="1.5708" effort="100" velocity="100"/>
   </joint>
   <joint type="fixed" name="right_hand_index_0_joint_offset">
      <parent link="right_hand_index_0_joint_jointbody"/>
      <child link="right_hand_index_0_link"/>
      <origin xyz="-0.0 -0.0 -0.0" rpy="0.0 0.0 0.0"/>
   </joint>
   <link name="right_hand_index_1_link">
      <inertial>
         <origin xyz="0.0262819 -0.00171735 -0.000107789" rpy="1.559819699036495 -0.010651911255361135 1.5597654091283988"/>
         <mass value="0.0203063"/>
         <inertia ixx="4.61314e-06" iyy="3.86645e-06" izz="1.53495e-06" ixy="0" ixz="0" iyz="0"/>
      </inertial>
      <visual name="right_hand_index_1_link">
         <origin xyz="0.02593452957629466 -0.00020477239635855674 0.00022412485371993442" rpy="1.6074363861535836 4.542416809050209e-05 1.5695571416902347"/>
         <geometry>
            <mesh filename="package://bheema/unitree_g1/meshes/converted_right_hand_index_1_link_b2b2b2ff.obj"/>
         </geometry>
      </visual>
      <visual name="right_hand_index_1_link">
         <origin xyz="0.02593452957629466 -0.00020477239635855674 0.00022412485371993442" rpy="1.6074363861535836 4.542416809050209e-05 1.5695571416902347"/>
         <geometry>
            <mesh filename="package://bheema/unitree_g1/meshes/converted_right_hand_index_1_link_808080ff.obj"/>
         </geometry>
      </visual>
   </link>
   <link name="right_hand_index_1_joint_jointbody">
      <inertial>
         <origin xyz="0.0 0.0 0.0" rpy="0.0 0.0 0.0"/>
         <mass value="0.001"/>
         <inertia ixx="1e-09" iyy="1e-09" izz="1e-09" ixy="0" ixz="0" iyz="0"/>
      </inertial>
   </link>
   <joint type="revolute" name="right_hand_index_1_joint">
      <parent link="right_hand_index_0_link"/>
      <child link="right_hand_index_1_joint_jointbody"/>
      <origin xyz="0.0458 0.0 0.0" rpy="0.0 0.0 0.0"/>
      <axis xyz="0.0 0.0 1.0"/>
      <limit lower="0.0" upper="1.74533" effort="100" velocity="100"/>
   </joint>
   <joint type="fixed" name="right_hand_index_1_joint_offset">
      <parent link="right_hand_index_1_joint_jointbody"/>
      <child link="right_hand_index_1_link"/>
      <origin xyz="-0.0 -0.0 -0.0" rpy="0.0 0.0 0.0"/>
   </joint>



   <ros2_control name="G1MujocoSystem" type="system">
   <hardware>
      <plugin>mujoco_ros2_control/MujocoSystemInterface</plugin>
      <param name="mujoco_model">/home/sid/projects25/src/bheema/unitree_g1/scene_with_hands.xml</param>
      <param name="sim_speed_factor">1.0</param>
   </hardware>

   <!-- Legs -->
   <joint name="left_hip_pitch_joint">
      <command_interface name="position"/>
      <state_interface name="position"/>
      <state_interface name="velocity"/>
   </joint>

   <joint name="left_hip_roll_joint">
      <command_interface name="position"/>
      <state_interface name="position"/>
      <state_interface name="velocity"/>
   </joint>

   <joint name="left_hip_yaw_joint">
      <command_interface name="position"/>
      <state_interface name="position"/>
      <state_interface name="velocity"/>
   </joint>

   <joint name="left_knee_joint">
      <command_interface name="position"/>
      <state_interface name="position"/>
      <state_interface name="velocity"/>
   </joint>

   <joint name="left_ankle_pitch_joint">
      <command_interface name="position"/>
      <state_interface name="position"/>
      <state_interface name="velocity"/>
   </joint>

   <joint name="left_ankle_roll_joint">
      <command_interface name="position"/>
      <state_interface name="position"/>
      <state_interface name="velocity"/>
   </joint>

   <!-- Right leg -->
   <joint name="right_hip_pitch_joint">
      <command_interface name="position"/>
      <state_interface name="position"/>
      <state_interface name="velocity"/>
   </joint>

   <joint name="right_hip_roll_joint">
      <command_interface name="position"/>
      <state_interface name="position"/>
      <state_interface name="velocity"/>
   </joint>

   <joint name="right_hip_yaw_joint">
      <command_interface name="position"/>
      <state_interface name="position"/>
      <state_interface name="velocity"/>
   </joint>

   <joint name="right_knee_joint">
      <command_interface name="position"/>
      <state_interface name="position"/>
      <state_interface name="velocity"/>
   </joint>

   <joint name="right_ankle_pitch_joint">
      <command_interface name="position"/>
      <state_interface name="position"/>
      <state_interface name="velocity"/>
   </joint>

   <joint name="right_ankle_roll_joint">
      <command_interface name="position"/>
      <state_interface name="position"/>
      <state_interface name="velocity"/>
   </joint>

   <!-- Waist -->
   <joint name="waist_yaw_joint">
      <command_interface name="position"/>
      <state_interface name="position"/>
      <state_interface name="velocity"/>
   </joint>

   <joint name="waist_roll_joint">
      <command_interface name="position"/>
      <state_interface name="position"/>
      <state_interface name="velocity"/>
   </joint>

   <joint name="waist_pitch_joint">
      <command_interface name="position"/>
      <state_interface name="position"/>
      <state_interface name="velocity"/>
   </joint>
   </ros2_control>

</robot>
